Traceback (most recent call last):
  File "/Users/feilong/miniconda3/envs/py/lib/python3.9/site-packages/jupyter_cache/executors/utils.py", line 51, in single_nb_execution
    executenb(
  File "/Users/feilong/miniconda3/envs/py/lib/python3.9/site-packages/nbclient/client.py", line 1112, in execute
    return NotebookClient(nb=nb, resources=resources, km=km, **kwargs).execute()
  File "/Users/feilong/miniconda3/envs/py/lib/python3.9/site-packages/nbclient/util.py", line 74, in wrapped
    return just_run(coro(*args, **kwargs))
  File "/Users/feilong/miniconda3/envs/py/lib/python3.9/site-packages/nbclient/util.py", line 53, in just_run
    return loop.run_until_complete(coro)
  File "/Users/feilong/miniconda3/envs/py/lib/python3.9/asyncio/base_events.py", line 642, in run_until_complete
    return future.result()
  File "/Users/feilong/miniconda3/envs/py/lib/python3.9/site-packages/nbclient/client.py", line 553, in async_execute
    await self.async_execute_cell(
  File "/Users/feilong/miniconda3/envs/py/lib/python3.9/site-packages/nbclient/client.py", line 857, in async_execute_cell
    self._check_raise_for_error(cell, exec_reply)
  File "/Users/feilong/miniconda3/envs/py/lib/python3.9/site-packages/nbclient/client.py", line 760, in _check_raise_for_error
    raise CellExecutionError.from_cell_and_msg(cell, exec_reply_content)
nbclient.exceptions.CellExecutionError: An error occurred while executing the following cell:
------------------
fig, axs = plt.subplots(1, 2, dpi=300, figsize=([1728 / 300 + 1, 1560 / 600]))
for i in range(2):
    if i == 0:
        v = rng.random((9372 + 9370, ))
        title = 'masked icoorder5'
    elif i == 1:
        v = rng.random((10242 * 2, ))
        title = 'non-masked icoorder5'
    img = brain_plot(v, vmax=1, vmin=0)
    ax.imshow(img)
    ax.axis('off')
    ax.set_title(title)
plt.show()
------------------

[0;31m---------------------------------------------------------------------------[0m
[0;31mNameError[0m                                 Traceback (most recent call last)
[0;32m<ipython-input-2-dfbddbbb5291>[0m in [0;36m<module>[0;34m[0m
[1;32m      8[0m         [0mtitle[0m [0;34m=[0m [0;34m'non-masked icoorder5'[0m[0;34m[0m[0;34m[0m[0m
[1;32m      9[0m     [0mimg[0m [0;34m=[0m [0mbrain_plot[0m[0;34m([0m[0mv[0m[0;34m,[0m [0mvmax[0m[0;34m=[0m[0;36m1[0m[0;34m,[0m [0mvmin[0m[0;34m=[0m[0;36m0[0m[0;34m)[0m[0;34m[0m[0;34m[0m[0m
[0;32m---> 10[0;31m     [0max[0m[0;34m.[0m[0mimshow[0m[0;34m([0m[0mimg[0m[0;34m)[0m[0;34m[0m[0;34m[0m[0m
[0m[1;32m     11[0m     [0max[0m[0;34m.[0m[0maxis[0m[0;34m([0m[0;34m'off'[0m[0;34m)[0m[0;34m[0m[0;34m[0m[0m
[1;32m     12[0m     [0max[0m[0;34m.[0m[0mset_title[0m[0;34m([0m[0mtitle[0m[0;34m)[0m[0;34m[0m[0;34m[0m[0m

[0;31mNameError[0m: name 'ax' is not defined
NameError: name 'ax' is not defined

